<mujocoinclude>
  <body name="torso" pos="-1 -1 1.75">
    <geom class="ant" name="torso_geom" pos="0 0 0" size="0.20" type="sphere"/>
    <joint armature="0" damping="0" limited="false" margin="0.01" name="root" pos="0 0 0" type="free"/>
    <!-- Front left leg -->
    <body name="front_left_leg" pos="0 0 0">
      <geom class="ant" fromto="0.0 0.0 0.0 -0.16 0.16 0.0" name="aux_1_geom" size="0.064" type="capsule"/>
      <body name="aux_11" pos="-0.16 0.16 0">
        <joint axis="0 0 1" name="hip_1" pos="0.0 0.0 0.0" range="-30 30" type="hinge"/>
        <geom class="ant" fromto="0.0 0.0 0.0 -0.16 0.16 0.0" name="front_left_leg_geom" size="0.064" type="capsule"/>
        <body name="aux_12" pos="-0.16 0.16 0">
          <joint axis="1 1 0" name="ankle_1" pos="0.0 0.0 0.0" range="-70 -30" type="hinge"/>
          <geom class="ant" fromto="0.0 0.0 0.0 -0.32 0.32 0.0" name="front_left_ankle_geom" size="0.064" type="capsule"/>
        </body>
      </body>
    </body>
    <!-- Front right leg -->
    <body name="front_right_leg" pos="0 0 0">
      <geom class="ant" fromto="0.0 0.0 0.0 0.16 0.16 0.0" name="aux_2_geom" size="0.064" type="capsule"/>
      <body name="aux_21" pos="0.16 0.16 0">
        <joint axis="0 0 1" name="hip_2" pos="0.0 0.0 0.0" range="-30 30" type="hinge"/>
        <geom class="ant" fromto="0.0 0.0 0.0 0.16 0.16 0.0" name="front_right_leg_geom" size="0.064" type="capsule"/>
        <body name="aux_22" pos="0.16 0.16 0">
          <joint axis="-1 1 0" name="ankle_2" pos="0.0 0.0 0.0" range="30 70" type="hinge"/>
          <geom class="ant" fromto="0.0 0.0 0.0 0.32 0.32 0.0" name="front_right_ankle_geom" size="0.064" type="capsule"/>
        </body>
      </body>
    </body>
    <!-- Back left leg -->
    <body name="back_left_leg" pos="0 0 0">
      <geom class="ant" fromto="0.0 0.0 0.0 -0.16 -0.16 0.0" name="aux_3_geom" size="0.064" type="capsule"/>
      <body name="aux_31" pos="-0.16 -0.16 0">
        <joint axis="0 0 1" name="hip_3" pos="0.0 0.0 0.0" range="-30 30" type="hinge"/>
        <geom class="ant" fromto="0.0 0.0 0.0 -0.16 -0.16 0.0" name="back_left_leg_geom" size="0.064" type="capsule"/>
        <body name="aux_32" pos="-0.16 -0.16 0">
          <joint axis="-1 1 0" name="ankle_3" pos="0.0 0.0 0.0" range="-70 -30" type="hinge"/>
          <geom class="ant" fromto="0.0 0.0 0.0 -0.32 -0.32 0.0" name="back_left_ankle_geom" size="0.064" type="capsule"/>
        </body>
      </body>
    </body>
    <body name="back_right_leg" pos="0 0 0">
      <geom class="ant" fromto="0.0 0.0 0.0 0.16 -0.16 0.0" name="aux_4_geom" size="0.064" type="capsule"/>
      <body name="aux_41" pos="0.16 -0.16 0">
        <joint axis="0 0 1" name="hip_4" pos="0.0 0.0 0.0" range="-30 30" type="hinge"/>
        <geom class="ant" fromto="0.0 0.0 0.0 0.16 -0.16 0.0" name="back_right_leg_geom" size="0.064" type="capsule"/>
        <body name="aux_42" pos="0.16 -0.16 0">
          <joint axis="1 1 0" name="ankle_4" pos="0.0 0.0 0.0" range="30 70" type="hinge"/>
          <geom class="ant" fromto="0.0 0.0 0.0 0.32 -0.32 0.0" name="back_right_ankle_geom" size="0.064" type="capsule"/>
        </body>
      </body>
    </body>
  </body>
</mujocoinclude>
